Workbook

Sheet 2018
E2: SEGUIMIENTO A COTIZACIONES
B10: Número de cotización | C10: Descripción de la cotización | J10: Valor sin IVA | K10: Fecha de cotización | L10: Fecha de aprobación | M10: Telefono | N10: Persona Encargada | O10: Correo
B13: 1 | C13: Cotización del diseño de extinción de incendios para el proyecto CDI Aures, de la ciudad de Medellín | J13: 2783000 | K13: 43229
B14: 2 | C14: Cotización diseño del diseño de extinción de incendios para el CEDI - Invesa | J14: 22176000 | K14: 43229
B15: 3 | C15: Cotización del diseño de extinción de incendios para el proyecto DISTRIHOGAR | J15: 5845000 | K15: 43230
B16: 4 | C16: COTIZACION DEL DISEÑO DE DETECCIÓN DE INCENDIOS PARA EL PROYECT COOPIMAR | J16: 3500000 | K16: 43230
B17: 5 | C17: COTIZACION DEL DISEÑO DE DETECCIÓN DE INCENDIOS PARA EL PROYECTO OLIVARI | J17: 1990000 | K17: 43231
B18: 6 | C18: COTIZACION DE LOS DISEÑOS DE PROTECCIÓN CONTRA INCENDIOS PARA EL PROYECTO BODEGA FAVITO | J18: 9980000 | K18: 43236
B19: 7 | C19: COTIZACION DE LOS DISEÑOS DE PROTECCIÓN CONTRA INCENDIOS PARA EL PROYECTO LOCAL 152 VIVA ENVIGADO | J19: 735000 | K19: 43236
B20: 8 | C20: COTIZACION DEL REDISEÑO Y VERIFICACIÓN DE CÁLCULOS HIDRÁULICOS PARA EL NUEVO CEDI DE INVESA, DE LA CIUDAD DE GIRARDOTA | J20: 10472000 | K20: 43238
B21: 9 | C21: COTIZACION DE LOS DISEÑOS DE PROTECCIÓN CONTRA INCENDIOS PARA AGUAS DEL BOSQUE | J21: 15092000 | K21: 43242
B22: 10 | C22: COTIZACION DE LOS DISEÑOS DE PROTECCIÓN CONTRA INCENDIOS LOCAL D1 | J22: 1540000 | K22: 43242
B23: 11 | C23: COTIZACION DE LOS DISEÑOS DE PROTECCIÓN CONTRA INCENDIOS AV EL POBLADO - AUTOCAD | J23: 19588800 | K23: 43243
C24: COTIZACION DE LOS DISEÑOS DE PROTECCIÓN CONTRA INCENDIOS AV EL POBLADO - REVIT | J24: 27104000 | K24: 43243 | L24: 43257
B25: 12 | C25: COTIZACION DEL ANÁLISIS DE SEGURIDAD HUMANA - PROYECTO MEDELLÍN | J25: 3670000 | K25: 43243 | L25: 43250
B26: 13 | C26: COTIZACION DEL ANÁLISIS DE SEGURIDAD HUMANA - PROYECTO ENVIGADO | J26: 3670000 | K26: 43243 | L26: 43250
B27: 14 | C27: COTIZACION DEL ANÁLISIS DE SEGURIDAD HUMANA - CUO CIUDADELA UNIVERSITARIA DE OCCIDENTE | J27: 5544000 | K27: 43243 | L27: 43245
B28: 15 | C28: COTIZACION DE LOS DISEÑOS DE PROTECCIÓN CONTRA INCENDIOS RESTAURANTE ASIA | J28: 1970000 | K28: 43248 | L28: 43250
B29: 16 | C29: COTIZACION DE LOS DISEÑOS DE PROTECCIÓN CONTRA INCENDIOS PARA EL PROYECTO CLÍNICA DE LA CIUDAD DE LA CEJA | J29: 16262400 | K29: 43248
B30: 17 | C30: COTIZACION DEL DISEÑO DE EXTINCIÓN DE INCENDIOS PARA EL PROYECTO LOCAL KÓNICO VIVA ENVIGADO | J30: 610000 | K30: 43249 | L30: 43297
B31: 18 | C31: COTIZACION DE LOS DISEÑOS DE DETECCIÓN DE INCENDIOS Y SEGURIDAD HUMANA PARA EL PROYECTO NUEVA FRONTERA | J31: 8000000 | K31: 43249 | L31: 43252
B32: 19 | C32: COTIZACION DE LOS DISEÑOS DE PROTECCIÓN CONTRA INCENDIOS Y SEGURIDAD HUMANA PARA EL PROYECTO MAZANTI | J32: 20328000 | K32: 43227
B33: 20 | C33: COTIZACION DEL DISEÑO DE DETECCIÓN DE INCENDIOS - PUERTO RIONEGRO Y CARGA FASE I | J33: 4174500 | K33: 43250
B34: 21 | C34: COTIZACION DE LOS DISEÑOS DE PROTECCIÓN CONTRA INCENDIOS PARA EL PROYECTO ON BUSINESS MILLA DE ORO | J34: 1830000 | K34: 43256
B35: 22 | C35: COTIZACION DE LOS DISEÑO DE PROTECCIÓN CONTRA INCENDIOS - OFICINAS BODEGA PREMEX | J35: 2340000 | K35: 43256
B36: 23 | C36: COTIZACION DEL DISEÑO DE DETECCIÓN DE INCENDIOS PARA EL TRES CANTOS, EN LA CIUDAD DE MEDELLÍN | J36: 6325000 | K36: 43258
B37: 24 | C37: COTIZACION DEL DISEÑO DE EXTINCIÓN DE INCENDIOS PARA EL PROYECTO CDI AURES | J37: 2783000 | K37: 43259
B38: 25 | C38: COTIZACION DE LOS DISEÑOS DE PROTECCIÓN CONTRA INCENDIOS PARA EL PROYECTO LORITO D´MODA | J38: 2710000 | K38: 43260
B39: 26 | C39: COTIZACION DE LOS DISEÑOS DE PROTECCIÓN CONTRA INCENDIOS PARA EL PROYECTO MERCADOS EL ÁGORA | J39: 5550000 | K39: 43260
B40: 27 | C40: COTIZACION DE LOS DISEÑOS DE PROTECCIÓN CONTRA INCENDIOS Y SEGURIDAD HUMANA PARA EL PROYECTO BORBÓN DE LA MONTAÑA | J40: 20328000 | K40: 43263
B41: 28 | C41: COTIZACION DE LOS DISEÑOS DE PROTECCIÓN CONTRA INCENDIOS Y SEGURIDAD HUMANA PARA EL PROYECTO BEILLIN | J41: 36344000 | K41: 43264
B42: 29 | C42: COTIZACION DE LOS DISEÑO DE PROTECCIÓN CONTRA INCENDIOS PARA EL PROYECTO NACAR | J42: 4930000 | K42: 43265 | L42: 43266
B43: 30 | C43: COTIZACION DE LOS DISEÑOS DE PROTECCIÓN CONTRA INCENDIOS Y SEGURIDAD HUMANA PARA EL PROYECTO COLISEO RUBEN DARIO QUINTERO VILLADA EN LA CIUDAD DE RIONEGRO | J43: 16016000 | K43: 43266
B44: 31 | C44: COTIZACION DE LOS DISEÑOS DE PROTECCIÓN CONTRA INCENDIOS Y SEGURIDAD HUMANA PARA EL PROYECTO HOJARASCA | J44: 6590000 | K44: 43267
B45: 32 | C45: COTIZACION DE LOS DISEÑOS DE PROTECCIÓN CONTRA INCENDIOS PARA EL PROYECTO LOCAL 324 – VIVA ENVIGADO | J45: 2170000 | K45: 43270
B46: 33 | C46: COTIZACION DE LOS DISEÑOS DE PROTECCIÓN CONTRA INCENDIOS PARA EL PROYECTO TRES33 | J46: 15400000 | K46: 43271
B47: 34 | C47: COTIZACION DE LOS DISEÑOS DE PROTECCIÓN CONTRA INCENDIOS PARA EL PROYECTO MANDALA | J47: 16400000 | K47: 43271
B48: 35 | C48: COTIZACION DE LA REVISIÓN DE LOS DISEÑOS DE EXTINCIÓN Y DETECCIÓN DE INCENDIOS DEL PROYECTO CIBELES | J48: 4250000 | K48: 43278
B49: 36 | C49: COTIZACION DEL DISEÑO Y DIMENCIONAMIENTO DE LAS CONEXIONES A LOS EDIFICIOS EXISTENTES DEL PROYECTO PLANTA CEMENTOS MOLINS | J49: 6160000 | K49: 43280
B50: 37 | C50: COTIZACION DEL DISEÑO DE DETECCIÓN DE INCENDIOS PARA EL PROYECTO CABLE EL PICACHO - DWG | J50: 6960000 | K50: 43282
...

Sheet 2019
E2: SEGUIMIENTO A COTIZACIONES
R4: Consecutivo repetido
R5: No encontre informacion
B10: Número de cotización | C10: Descripción de la cotización | J10: Valor sin IVA | K10: Fecha de cotización | L10: Fecha de aprobación | M10: Telefono | N10: Persona Encargada | O10: Correo
B13: 1 | C13: Cotización de la actualización de planos record y rediseño de los sistemas de extinción de incendio para la Terminal de Servicios Aeroportuarios Aeropuerto El Caño Quibdo | J13: 33000000 | K13: 43468 | N13: Juan Camilo Quintero
B14: 2 | C14: COTIZACION DEL REDISEÑO DE DETECCIÓN DE INCENDIOS PARA EL PROYECTO METROCABLE PICACHO | J14: 4450000 | K14: 43468 | N14: Bayron Eliecer Puerta
B15: 3 | C15: COTIZACION DEL DISEÑO DE EXTINCIÓN DE INCENDIOS PARA EL PROYECTO MAM MUSEO DE ARTE MODERNO | J15: 20480000 | K15: 43469 | N15: Julián Suárez Estrada
B16: 4 | C16: COTIZACION DE REVISIÓN DEL SISTEMAS DE EXTINCIÓN DE INCENDIOS PARA LOS LOCALES DEL CENTRO COMERCIAL PALMA GRANDE | J16: 3295000 | K16: 43474 | N16: David Lopera
B17: 5 | C17: COTIZACION DE LOS DISEÑOS DE PROTECCIÓN CONTRA INCENDIOS - CASA RONALD MCDONALD | J17: 3442 | K17: 43474 | N17: Julio Alejandro Llamas
B18: 6 | C18: COTIZACION DE LOS DISEÑOS DE PROTECCIÓN CONTRA INCENDIOS Y SEGURIDAD HUMANA PARA EL PROYECTO EDIFICIO MARIALUCI | J18: 4990000 | K18: 43476 | N18: Jhon Rodriguez
B19: 6 | C19: COTIZACION DE LOS DISEÑOS DE PROTECCIÓN CONTRA INCENDIOS Y SEGURIDAD HUMANA PARA EL PROYECTO EDIFICIO MARIALUCI | J19: 4990000 | K19: 43476 | N19: Johrladiz Úsuga
B20: 7 | C20: COTIZACION DE LOS DISEÑOS DE SEGURIDAD HUMANA Y DETECCIÓN DE INCENDIOS - CANTAZARO | J20: 6000000 | K20: 43479 | N20: José Ignacio Aristizabal
B21: 8 | C21: COTIZACION DE LOS DISEÑOS DE PROTECCIÓN CONTRA INCENDIOS PARA EL PROYECTO COLEGIO UCO CIMARRONAS | J21: 3930000 | K21: 43479 | N21: Estevan Castaño
B22: 9 | C22: COTIZACION DE LOS DISEÑOS DE PROTECCIÓN CONTRA INCENDIOS PARA EL PROYECTO BRISAS DEL SOL 3 | J22: 16800000 | K22: 43479 | N22: Estevan Castaño | O22: estevancastano@gmail.com
B23: 10 | C23: COTIZACION DE LOS DISEÑOS DE PROTECCIÓN CONTRA INCENDIOS - PTAR PAPELSA | J23: 11270000 | K23: 43480 | N23: Diana Carolina Jaramillo
B24: 11 | C24: COTIZACION DEL DISEÑO DE LA RED DE EXTINCIÓN DE INCENDIOS - TROPIGAS SANTO TOMAS | J24: 16016 | K24: 43481 | N24: Julio Alejandro Llamas
B25: 12 | C25: COTIZACION ESTIMADA DE LOS DISEÑOS DE PROTECCIÓN CONTRA INCENDIOS Y SEGURIDAD HUMANA PARA PROYECTOS DE CONSTRUCIÓN Y REMODELACIÓN | J25: Variable | K25: 43486 | N25: Catalina Prieto
B26: 13 | C26: COTIZACION DEL DISEÑO DE EXTINCIÓN DE INCENDIOS PARA EL PROYECTO ALIMENTOS NUOVO PLANTA LA ESTRELLA | J26: 6130000 | K26: 43486 | N26: Carlos Esteban Longas Vélez
B27: 14 | C27: COTIZACION DE LOS DISEÑOS DE PROTECCIÓN CONTRA INCENDIOS PARA EL PROYECTO EVERFIT LA 65 | J27: 3775000 | K27: 43121 | N27: Adriana Jiménez
B28: 15 | C28: COTIZACION DEL DISEÑO DE EXTINCIÓN DE INCENDIOS PARA EL PROYECTO ALIMENTOS NUOVO PLANTA LA ESTRELLA | J28: 4590000 | K28: 43488 | N28: Juan Pablo Grajales
B29: 16 | C29: COTIZACION DEL DISEÑO DE EXTINCIÓN DE INCENDIOS - DATACENTER | J29: 6590000 | K29: 43487 | N29: Daniel Felipe Díaz Beltrán M.Eng.
B30: 17 | C30: COTIZACION DE LOS DISEÑOS DE PROTECCIÓN CONTRA INCENDIOS PARA EL PROYECTO COLEGIO MONSEÑOR ALFONSO URIBE JARAMILLO | J30: 4470000 | K30: 43489 | N30: Edinson Franco
B31: 18 | C31: COTIZACION DE LOS DISEÑOS DE PROTECCIÓN CONTRA INCENDIOS - LOCAL DECORCERÁMICA LLANOGRANDE | J31: 2600000 | K31: 43490 | N31: Jairo Andrés Moncada C.
B32: 19 | C32: COTIZACION DE LOS DISEÑOS DE SEGURIDAD HUMANA Y PROTECCIÓN CONTRA INCENDIOS - LOS MELGUIZO | J32: 31790000 | K32: 43490 | N32: Jhon Anderson Rodriguez
B33: 19 | C33: COTIZACIÓN DE ACTUALIZACIÓN DE PLANOS RECORD Y REDISEÑO DE EXTINCIÓN DE INCENDIOS PARA EL AEROPUERTO EL CAÑO QUIBDÓ | J33: 33000000 | K33: 43468 | N33: Juan Camilo Quintero
B34: 20 | C34: COTIZACION DE LOS DISEÑOS DE PROTECCIÓN CONTRA INCENDIOS PARA EL PROYECTO MALL CIMARRONAS | J34: 9480000 | K34: 43490 | N34: Oscar Salazar
B35: 21 | C35: COTIZACION DEL ANÁLISIS DE SEGURIDAD HUMANA Y PROTECCIÓN CONTRA INCENDIOS - DAVITA | J35: 1950000 | K35: 43493 | N35: Otalvaro Osorio Correa
B36: 22 | C36: COTIZACION DE LOS DISEÑOS DE DE EXTINCIÓN Y DETECCIÓN INCENDIOS - COMFAMA | J36: Variable | K36: 43494 | N36: Ariel Gómez Ruíz
B37: 23 | C37: COTIZACION DEL DISEÑO DE EXTINCIÓN DE INCENDIOS - FEDEX AEROPUERTO RIONEGRO | J37: 8153000 | K37: 43494 | N37: Juan Camilo Quintero Bedoya
B38: 24 | C38: COTIZACION DE LOS DISEÑOS DE PROTECCIÓN CONTRA INCENDIOS - EDIFICIO INTERES SOCIAL LA ESTRELLA | J38: 10865000 | K38: 43494 | N38: Jorge Ruiz E.
B39: 25 | C39: COTIZACION DE LOS DISEÑOS DE SEGURIDAD HUMANA Y PROTECCIÓN CONTRA INCENDIOS - AKI | J39: 32190000 | K39: 43494 | N39: Maribel Osorio
B40: 26 | C40: COTIZACION DE LOS DISEÑOS DE SEGURIDAD HUMANA Y PROTECCIÓN CONTRA INCENDIOS - CASA CASTELLANA | J40: 17491000 | K40: 43494 | N40: Fernando Saldarriaga
B41: 27 | C41: COTIZACION DE LOS DISEÑOS DE SEGURIDAD HUMANA Y PROTECCIÓN CONTRA INCENDIOS - VOLARÉ | J41: 20584000 | K41: 43494 | N41: Fernando Saldarriaga
B42: 28 | C42: COTIZACION DE LOS DISEÑOS DE SEGURIDAD HUMANA Y PROTECCIÓN CONTRA INCENDIOS - VOLARÉ | J42: 20584000 | K42: 43495
A43: ok | B43: 29 | C43: COTIZACION DEL DISEÑO DE DETECCIÓN DE INCENDIOS PARA EL COLEGIO THE NEW SCHOOL | J43: 2980000 | K43: 43496 | N43: Jorge García
A44: ok | B44: 29 | C44: COTIZACION DE LOS DISEÑOS DE SEGURIDAD HUMANA Y PROTECCIÓN CONTRA INCENDIOS - VOLARÉ | J44: Variable | K44: 43495 | N44: Estevan Castaño | O44: estevancastano@gmail.com
B45: 30 | C45: COTIZACION DEL DISEÑO DE EXTINCIÓN DE INCENDIOS PARA EL PROYECTO LOCAL 114 DE JARDINES DE LLANOGRANDE | J45: 320000 | K45: 43496 | N45: David Lopera
B46: 31 | C46: COTIZACION DE LOS DISEÑOS DE PROTECCIÓN CONTRA INCENDIOS PARA EL PROYECTO SUMIMEDICAL | J46: 10835000 | K46: 43131 | N46: Cristiam Mondragón
B47: 32 | C47: COTIZACION DEL DISEÑO DE EXTINCIÓN DE INCENDIOS PARA EL PROYECTO LOCAL 113 DE JARDINES DE LLANOGRANDE | J47: 320000 | K47: 43500 | N47: David Lopera
B48: 33 | C48: COTIZACION DEL DISEÑO DE EXTINCIÓN DE INCENDIOS PARA EL PROYECTO LOCAL 129 DE JARDINES DE LLANOGRANDE | J48: 320000 | K48: 43500 | N48: David Lopera
...

Sheet 2020
H1: COTIZACION REVISIÓN Y CONSULTORÍA DEL SISTEMA DE EXTINCIÓN DE INCENDIOS ENTREPINOS
E2: SEGUIMIENTO A COTIZACIONES
S5: Consecutivo repetido
S6: No encontre informacion
B10: Número de cotización | C10: Descripción de la cotización | J10: Cliente | K10: Valor sin IVA | L10: Fecha de cotización | M10: Fecha de aprobación | N10: Telefono | O10: Persona Encargada | P10: Correo
B13: 1 | C13: COTIZACION DEL DISEÑO DE EXTINCIÓN DE INCENDIOS - OLIVE | J13: Scala | K13: 8127000 | L13: 43837 | N13: 3006195142 | O13: Jose Ignacio Echeverri | P13: interventoriaolive@gmail.com
B14: 2 | C14: COTIZACION DEL DISEÑO DE EXTINCIÓN DE INCENDIOS - MEDICOA PISO 1 URGENCIAS | J14: SPCI | K14: 2130000 | L14: 43837 | N14: 3104680508 | O14: Juan Pablo Grajales | P14: juan.grajales@spci.com.co
B15: 3 | C15: COTIZACION DE LOS DISEÑOS DE SEÑALIZACION DE EMERGENCIA Y EXTINTORES PORTÁTILES - BIKE HOUSE | J15: HyM | K15: 1500000 | L15: 43838 | N15: 3014487912 | O15: Evelin Rojas | P15: hidraulicaymontajes@gmail.com
B16: 4 | C16: COTIZACION DE LOS DISEÑOS DE PROTECCIÓN CONTRA INCENDIOS Y SEGURIDAD HUMANA PARA EL PROYECTO SELVA TORRE 1 | J16: SPCI | K16: 10660000 | L16: 43838 | N16: 3104680508 | O16: Juan Pablo Grajales | P16: juan.grajales@spci.com.co
B17: 5 | C17: COTIZACION DE LOS DISEÑOS DE PROTECCIÓN CONTRA INCENDIOS Y SEGURIDAD HUMANA PARA EL PROYECTO SELVA COMPLETO | J17: SPCI | K17: 16935000 | L17: 43838 | N17: 3104680508 | O17: Juan Pablo Grajales | P17: juan.grajales@spci.com.co
B18: 6 | C18: COTIZACION DEL DISEÑO DE EXTINCIÓN DE INCENDIOS - GRUPO DIANA | J18: SPCI | K18: 43900000 | L18: 43840 | N18: 3104680508 | O18: Juan Pablo Grajales | P18: juan.grajales@spci.com.co
B19: 7 | C19: COTIZACION DE LOS DISEÑOS DE PROTECCIÓN CONTRA INCENDIOS - CONSULTORIO 405 CITY MEDICA | J19: SOCOMES | K19: 900000 | L19: 43843 | N19: 3137851941 | O19: David Lopera | P19: david.lopera@socomes.com
B20: 8 | C20: COTIZACION DEL DISEÑO DE EXTINCIÓN DE INCENDIOS - SALA DE LACTANCIA VIVA BARRANQUILLA | J20: SPCI | K20: 900000 | L20: 43843 | M20: X | N20: 3104680508 | O20: Juan Pablo Grajales | P20: juan.grajales@spci.com.co
B21: 9 | C21: COTIZACION DEL DISEÑO DE EXTINCIÓN DE INCENDIOS - PUNTO CERO HYM VIVA BARRANQUILLA | J21: SPCI | K21: 1200000 | L21: 43843 | M21: X | N21: 3104680508 | O21: Juan Pablo Grajales | P21: juan.grajales@spci.com.co
B22: 10 | C22: COTIZACION DE LOS DISEÑOS DE SEGURIDAD HUMANA Y PROTECCIÓN CONTRA INCENDIOS - ADECUACIÓN OFICINA ISA 300 M2 | J22: ENSAMBLE | K22: 3670000 | L22: 43844 | M22: X | O22: Paola A. López Cadavid
B23: 11 | C23: COTIZACION DE LOS DISEÑOS DE PROTECCIÓN CONTRA INCENDIOS Y SEGURIDAD HUMANA PARA EL PROYECTO BODEGA CALDAS PRIMAVERA | J23: SPCI | K23: 19460000 | L23: 43846 | N23: 3104680508 | O23: Juan Pablo Grajales | P23: juan.grajales@spci.com.co
B24: 12 | C24: REVISIÓN DE LOS DISEÑOS DE EXTINCIÓN DE INCENDIOS PARA EL PROYECTO WE WORK ANTEJARDIN | J24: SPCI | K24: 1500000 | L24: 43967 | N24: 3104680508 | O24: Juan Pablo Grajales | P24: juan.grajales@spci.com.co
B25: 13 | C25: COTIZACION DE LOS DISEÑOS DE PROTECCIÓN CONTRA INCENDIOS Y SEGURIDAD HUMANA PARA EL PROYECTO VALLE CENTRAL | J25: SAHA | K25: 8780000 | L25: 43851 | O25: Carlos Darío Mejía
B26: 14 | C26: COTIZACION DE LOS DISEÑOS DE SEGURIDAD HUMANA Y PROTECCIÓN CONTRA INCENDIOS - IE VILLAS DE ARANJUEZ | J26: ESTUDIO CENTRAL | K26: 16000000 | L26: 43851 | M26: X | O26: Alejandro Restrepo Montoya
B27: 15 | C27: COTIZACION DE LOS DISEÑOS DE SEGURIDAD HUMANA Y PROTECCIÓN CONTRA INCENDIOS - PALACIO MUNICIPAL ENVIGADO | J27: LAUREANO FORERO | K27: 19435000 | L27: 43854 | O27: David Gómez
B28: 16 | C28: COTIZACION DE LOS DISEÑOS DE SEGURIDAD HUMANA Y PROTECCIÓN CONTRA INCENDIOS - PAJARO LIMON | J28: PAJARO LIMON | K28: 1305000 | L28: 43489 | O28: Pájaro limón
B29: 17 | C29: COTIZACION DE LOS DISEÑOS DE PROTECCIÓN CONTRA INCENDIOS Y SEGURIDAD HUMANA PARA EL PROYECTO PORTAL DE CANEY | J29: ESTEVAN CASTAÑO | K29: 7940000 | L29: 43493 | O29: Estevan Castaño
B30: 18 | C30: COTIZACION DE LOS DISEÑOS DE PROTECCIÓN CONTRA INCENDIOS Y SEGURIDAD HUMANA PARA EL PROYECTO PARTEQUIPOS | J30: JORGE COLORADO | K30: 25710000 | L30: 43859 | O30: Jorge Humberto Colorado
B31: 19 | C31: COTIZACION DEL DISEÑO DE EXTINCIÓN DE INCENDIOS - TINKKO | J31: HYM | K31: 2500000 | L31: 43860 | O31: Evelin Rojas
B32: 20 | C32: COTIZACIÓN DE LOS PLANOS AS-BUILT DE LA RED GENERAL DE EXTINCIÓN DE INCENDIOS DEL PROYECTO PIZARRA | J32: SPCI | K32: 675000 | L32: 43860 | N32: 3137546144 | O32: Juan Camilo Quintero | P32: proyectos1spci@gmail.com
B33: 21 | C33: COTIZACION DE LOS DISEÑOS DE PROTECCIÓN CONTRA INCENDIOS PARA EL PROYECTO CASA DE LA CULTURA JARDÍN | J33: CIVILSA | K33: 4140000 | L33: 43861 | O33: Julio Alzate
B34: 22 | C34: COTIZACION DE LOS DISEÑOS DE PROTECCIÓN CONTRA INCENDIOS Y SEGURIDAD HUMANA PARA EL PROYECTO VECINO PATIO | J34: ALG PROYECTOS | K34: 3700000 | L34: 43861 | O34: Juan Londoño
B35: 23 | C35: DISEÑOS DE EXTINTORES PORTÁTILES CONTRA INCENDIOS PARA BANCOLOMBIA FLORIDA PARQUE | J35: CONDISEÑO | K35: 1000000 | L35: 43833 | N35: 3175594091 | O35: Nakary García Romero | P35: n.garcia@condiseno.co
B36: 24 | C36: COTIZACION DISEÑO DETECCION HOTEL TEQUENDAMA | J36: RAPIDO | K36: VARIABLE | L36: 43864 | O36: Álvaro Manosalva
B37: 25 | C37: COTIZACION DEL DISEÑO DE DETECCIÓN DE INCENDIOS - TORRE 2 UNIVERSIDAD REMINGTON | J37: SERVICIOS IPM | K37: 4990000 | L37: 43865 | O37: Juan Santiago Londoño Quiceno
B38: 25 | C38: DISEÑO DE DETECCIÓN DE INCENDIOS PARA EL PROYECTO TORRE 2 UNIVERSIDAD REMINGTON | J38: UNIREMINGTON | K38: 5590000 | L38: 43881 | O38: Gloria María González Villa
B39: 26 | C39: COTIZACION DE LOS DISEÑOS DE SEGURIDAD HUMANA Y PROTECCIÓN CONTRA INCENDIOS - COMEDOR CLÍNICA LAS AMÉRICAS | J39: INTERVÉ | K39: 3765000 | L39: 43866 | O39: Martha Lucía Ferrer
B40: 27 | C40: COTIZACION DE LOS DISEÑOS DE PROTECCIÓN CONTRA INCENDIOS Y SEGURIDAD HUMANA PARA EL PROYECTO CITADELLA JERUSALEN | J40: SOCOMES | K40: 13920000 | L40: 43867 | N40: 3137851941 | O40: David Lopera | P40: david.lopera@socomes.com
B41: 28 | C41: COTIZACION DEL DISEÑO DE DETECCIÓN DE INCENDIOS - ALMACENAMIENTO DE 60.000 BRLS CHACHAGÜI – NARIÑO | J41: SPCI | K41: 6915000 | L41: 43869 | N41: 310 4278593 | O41: Daniel Uribe | P41: duribe86@gmail.com
B42: 29 | C42: COTIZACION DEL DISEÑO DE EXTINCIÓN DE INCENDIOS - TUGO | J42: TUGO | K42: 13550000 | L42: 43869 | O42: Leidy Johana Alarcón
B43: 30 | C43: COTIZACION DE LOS DISEÑOS DE PROTECCIÓN CONTRA INCENDIOS Y SEGURIDAD HUMANA PARA EL PROYECTO MANOS ACTIVAS | J43: ESTEVAN CASTAÑO | K43: 6270000 | L43: 43873 | O43: Estevan Castaño
B44: 31 | C44: COTIZACION DEL DISEÑO DE EXTINCIÓN DE INCENDIOS - TH EL TESORO | J44: SERVICIOS BYR | K44: 1055000 | L44: 43873 | O44: Sergio Andrés Ramos Carmona
B45: 32 | C45: COTIZACION DEL DISEÑO DE DETECCIÓN DE INCENDIOS - PROYECTO GO | J45: FCR SAS | K45: 5500000 | L45: 43874 | M45: X | O45: Judith Elena Trujillo R
B46: 33 | C46: COTIZACION DE LOS DISEÑOS DE PROTECCIÓN CONTRA INCENDIOS EXTERIORES PARA EL PROYECTO FIC-NORTE | J46: AIA | K46: 21320000 | L46: 43875 | O46: Francisco Posada
B47: 34 | C47: COTIZACION DE LOS DISEÑOS DE PROTECCIÓN CONTRA INCENDIOS - EDIFICIO CARMEN VIBORAL CONCIVELSA | J47: MAKROHABITAT | K47: 7605000 | L47: 43875 | O47: David Vélez
...

Sheet 2021
E2: SEGUIMIENTO A COTIZACIONES
S5: Consecutivo repetido
S6: No encontre informacion
B10: Número de cotización | C10: Descripción de la cotización | J10: Cliente | K10: Valor sin IVA | L10: Fecha de cotización | M10: Fecha de aprobación | N10: Telefono | O10: Persona Encargada | P10: Correo
B13: 1 | C13: COTIZACION DE LOS DISEÑOS DE PROTECCIÓN CONTRA INCENDIOS - CLUB HOUSE VIVA ENVIGADO | J13: AREAS FLEXIBLES | K13: 2850000 | L13: 44202 | N13: 319 280 96 29 | O13: Andrés López Gallón | P13: arquitecto@areasflexibles.com
B14: 2 | C14: COTIZACION DE LOS DISEÑOS DE SEGURIDAD HUMANA Y PROTECCIÓN CONTRA INCENDIOS - BANCOLOMBIA FIC48 | J14: STUDIO SUR | K14: 19930000 | L14: 44209 | N14: 3134669894 | O14: Andrea Sanchez | P14: andrea.sanchez@studiosur.net
B15: 3 | C15: COTIZACION DE LOS DISEÑOS DE SEGURIDAD HUMANA Y PROTECCIÓN CONTRA INCENDIOS - EDIFICIO CATTLEYA | J15: SPCI | K15: 19940000 | L15: 44209 | N15: 3104680508 | O15: Juan Pablo Grajales | P15: juan.grajales@spci.com.co
B16: 4 | C16: COTIZACION DE LOS DISEÑOS DE SEGURIDAD HUMANA Y PROTECCIÓN CONTRA INCENDIOS - BORAL RIONEGRO | J16: MÉNSULA | K16: 19950000 | L16: 44210 | N16: 3207091752 | O16: Cristian Londoño Montoya | P16: cristianlondono@mensulaingenieros.com
B17: 5 | C17: COTIZACION DIAGNÓSTICO SEGURIDAD HUMANA Y PROTECCIÓN CONTRA INCENDIOS - La FLA | J17: RISK | K17: 6000000 | L17: 44211 | N17: 3104473509 | O17: Carlos Alberto Gil Valencia | P17: carlos.gil@risksg.com
B18: 6 | C18: COTIZACION DE LOS DISEÑOS DE PROTECCIÓN CONTRA INCENDIOS - LABORATORIO CLINICA LAS AMÉRICAS | J18: INTERVÉ | K18: 3580000 | L18: 44211 | N18: 57(4) 352 3434 | O18: Humberto Acevedo | P18: hacevedo@interve.co
B19: 7 | C19: COTIZACION DE LOS DISEÑOS DE SEGURIDAD HUMANA Y PROTECCIÓN CONTRA INCENDIOS - EDIFICIO BLOQUE 3 SONSÓN UDEA | J19: SERVICIOS IPM | K19: 7200000 | L19: 44214 | M19: X | N19: 3015421412 | O19: Juan Londoño | P19: juan.londono@serviciosipm.com
B20: 8 | C20: COTIZACION DE LOS DISEÑOS DE SEGURIDAD HUMANA Y PROTECCIÓN CONTRA INCENDIOS - CAMPO NUEVO | J20: SECURETEC | K20: 14450000 | L20: 44214 | N20: 312 405 4584 | O20: Maribel Osorio | P20: ascomercial@securetec.com.co
B21: 9 | C21: COTIZACION PLANOS ASBUILT PLAZA FABRICATO PISO 1 | J21: SPCI | K21: 750000 | L21: 44215 | N21: 3104165783 | O21: Cristiam Mondragón | P21: cristiamondragon.spci@gmail.com
B22: 10 | C22: COTIZACION DEL DISEÑO DE DETECCIÓN DE INCENDIOS - MALL COMERCIAL CIMARRONAS | J22: CIMARRONAS | K22: 3500000 | L22: 44216 | N22: 301 3859970 | O22: Juan Carlos Gallego | P22: sptcimarronas@gmail.com
B23: 11 | C23: COTIZACION DE LOS DISEÑOS DE PROTECCIÓN CONTRA INCENDIOS - PLANTA RIONEGRO CLC | J23: SPCI | K23: 9900000 | L23: 44216 | N23: 3104680508 | O23: Juan Pablo Grajales | P23: juan.grajales@spci.com.co
B24: 12 | C24: COTIZACION DE LOS DISEÑOS DE SEGURIDAD HUMANA Y PROTECCIÓN CONTRA INCENDIOS - PLANTA RDC INDURAL | J24: DGB | K24: 13950000 | L24: 44217 | N24: 3127075530 | O24: Paula Jimenez | P24: pjimenezdgb@gmail.com
B25: 13 | C25: COTIZACION DEL DISEÑO DE DETECCIÓN DE INCENDIOS - ACRE | J25: CASA SANA | K25: 4950000 | L25: 44221 | N25: 3108945703 | O25: Jose Estrada | P25: joseestrada@casasana.com.co
B26: 14 | C26: COTIZACION CONCEPTO TÉCNICO DE PROTECCIÓN TANQUE DE ACPM EDIFICIO EPM | J26: INFRATELCO | K26: 2650000 | L26: 44221 | M26: X | N26: 312 7726924 | O26: Andres Muñoz | P26: infratelcosas@gmail.com
B27: 15 | C27: COTIZACION DEL DISEÑO DE EXTINCIÓN DE INCENDIOS PARA EL PROYECTO BODEGA SECADO ECOCEMENTOS | J27: SPCI | K27: 6900000 | L27: 44221 | N27: 3137546144 | O27: Juan Camilo Quintero | P27: proyectos1spci@gmail.com
B28: 16 | C28: COTIZACION DE LOS DISEÑOS DE PROTECCIÓN CONTRA INCENDIOS - ALAMEDA | J28: ARPRE | K28: 1550000 | L28: 44225 | N28: 3052925725 | O28: Luz Marina Restrepo | P28: elarpre.deco@gmail.com
B29: 17 | C29: COTIZACION DEL ANÁLISIS DE SEGURIDAD HUMANA - HOUSSING | J29: JHON ARISTIZABAL | K29: 2250000 | L29: 44225 | N29: 311 4337099 | O29: John Aristizabal | P29: jad@unoendiez.com.co
B30: 18 | C30: COTIZACION DE LOS DISEÑOS DE PROTECCIÓN CONTRA INCENDIOS - AGN PERÚ | J30: FPSG | K30: 17540 | L30: 44225 | N30: 3108227462 | O30: Álvaro Manosalva | P30: alvaromanosalva@sfiregroup.com
B31: 19 | C31: COTIZACION DE LOS DISEÑOS DE SEGURIDAD HUMANA Y PROTECCIÓN CONTRA INCENDIOS - CAOBA | J31: SPCI | K31: 23460000 | L31: 44225 | N31: 4487724 | O31: Laura Montoya | P31: lmontoyaspci@gmail.com
B32: 20 | C32: COTIZACION DE LOS DISEÑOS DE SEGURIDAD HUMANA Y PROTECCIÓN CONTRA INCENDIOS - PRATO | J32: SPCI | K32: 21190000 | L32: 44225 | N32: 4487725 | O32: Laura Montoya | P32: lmontoyaspci@gmail.com
B33: 21 | C33: COTIZACION DE LOS DISEÑOS DE SEGURIDAD HUMANA Y PROTECCIÓN CONTRA INCENDIOS - LIVORINO | J33: SPCI | K33: 21190000 | L33: 44225 | N33: 4487726 | O33: Laura Montoya | P33: lmontoyaspci@gmail.com
B34: 22 | C34: COTIZACION DE LOS DISEÑOS DE SEGURIDAD HUMANA Y PROTECCIÓN CONTRA INCENDIOS - BODEGA ITAGUÍ LAFLA | J34: GINO | K34: 25710000 | L34: 44225 | N34: 3113396273 | O34: Gino Montoya | P34: gino1037@hotmail.com
B35: 23 | C35: COTIZACION DE LOS DISEÑOS DE SEGURIDAD HUMANA Y PROTECCIÓN CONTRA INCENDIOS - ENTREMONTES | J35: INGENIERÍA Y VIVIENDA | K35: 19950000 | L35: 44229 | N35: 3124592 | O35: Alejandro Yepes | P35: alejandroyepes@ingenieriayvivienda.com
B36: 24 | C36: COTIZACION DE LOS DISEÑOS DE SEGURIDAD HUMANA Y PROTECCIÓN CONTRA INCENDIOS - TOPICARIO | J36: TROPICARIO | K36: 7550000 | L36: 44229 | N36: 300 864 37 10 | O36: Cristina Palacio Pérez | P36: cristinapalacio@mensulaingenieros.com
B37: 25 | C37: COTIZACION DE LOS DISEÑOS DE SEGURIDAD HUMANA Y PROTECCIÓN CONTRA INCENDIOS - SIER BUCARAMANGA | J37: ENSAMBLE | K37: 3250000 | L37: 44229 | N37: 3117477239 | O37: Paola López Cadavid | P37: paolopez@ensambleespaciosvivos.com
B38: 26 | C38: COTIZACION DE LOS DISEÑOS DE EXTINCIÓN DE INCENDIOS - ACUARELA DEL RIO | J38: SPCI | K38: 10035000 | L38: 44230 | N38: 3104203649 | O38: Mauricio Guzman | P38: mauroguzmanspci@gmail.com
B39: 27 | C39: COTIZACION DE LOS DISEÑOS DE SEGURIDAD HUMANA Y PROTECCIÓN CONTRA INCENDIOS - ZIMA | J39: SOCOMES | K39: 11920000 | L39: 44230 | N39: 3137851941 | O39: David Lopera | P39: david.lopera@socomes.com
B40: 28 | C40: COTIZACION DEL ANÁLISIS DE SEGURIDAD HUMANA PARA EL PROYECTO BLOQUE 42 A UNAL | J40: UNAL | K40: 3500000 | L40: 44230 | N40: 3113396273 | O40: Gino Montoya | P40: gino1037@hotmail.com
B41: 29 | C41: COTIZACION DEL DISEÑO DE DETECCIÓN DE INCENDIOS - VINOS Y LICORES SAS | J41: SPCI | K41: 9880000 | L41: 44230 | N41: 3104680508 | O41: Juan Pablo Grajales | P41: juan.grajales@spci.com.co
B42: 30 | C42: COTIZACION DE LOS DISEÑOS DE SEGURIDAD HUMANA Y PROTECCIÓN CONTRA INCENDIOS - PLANTA DE ALIMENTOS GUARNE | J42: SOCOMES | K42: 24960000 | L42: 44231 | N42: 3137851941 | O42: David Lopera | P42: david.lopera@socomes.com
B43: 31 | C43: COTIZACION DE LOS DISEÑOS DE SEGURIDAD HUMANA Y PROTECCIÓN CONTRA INCENDIOS - BANCOLOMBIA FIC48 | J43: ESPIRAL | K43: 18190000 | L43: 44231 | N43: 3207198907 | O43: Cristian Marín | P43: cristian.marin@espiral.com.co
B44: 32 | C44: COTIZACION DEL DISEÑO DE DETECCIÓN DE INCENDIOS PARA EL PROYECTO LA MARINA | J44: SPCI | K44: 3760000 | L44: 44231 | M44: X | N44: 3104680508 | O44: Juan Pablo Grajales | P44: juan.grajales@spci.com.co
B45: 33 | C45: COTIZACION DEL ANÁLISIS DE SEGURIDAD HUMANA PARA EL PROYECTO CAMPO NUEVO | J45: ADMIRIS | K45: 2000000 | L45: 44231 | M45: X | N45: 3014188503 | O45: Andrés Velázquez | P45: avelasquez@admirisltda.com
B46: 34 | C46: COTIZACION DEL DISEÑO DE DETECCIÓN DE INCENDIOS PARA EL PROYECTO PLANTA ITAGUÍ | J46: COLPA | K46: 6270000 | L46: 44232 | N46: 3014325966 | O46: Juan Camilo Betancur | P46: colpafireinnovationsas@gmail.com
B47: 35 | C47: COTIZACION DEL ANÁLISIS DE SEGURIDAD HUMANA PARA EL PROYECTO BLOQUE 42 A UNAL | J47: ADMIRIS | K47: 2500000 | L47: 44236 | N47: 3014188503 | O47: Andrés Velázquez | P47: avelasquez@admirisltda.com
B48: 36 | C48: COTIZACION DEL ANÁLISIS DE SEGURIDAD HUMANA PARA EL PROYECTO CENTRO DE NEGOCIOS SUR | J48: ADMIRIS | K48: 250000 | L48: 44236 | M48: X | N48: 3014188503 | O48: Andrés Velázquez | P48: avelasquez@admirisltda.com
...

Sheet 2022
E3: SEGUIMIENTO A COTIZACIONES
B11: Número de cotización | C11: Descripción de la cotización | J11: Cliente | K11: Valor sin IVA | L11: Fecha de cotización | M11: Aprobado | N11: Telefono | O11: Persona Encargada | P11: Correo
B12: 1 | C12: COTIZACION DEL DISEÑO DE EXTINCIÓN DE INCENDIOS PARA EL PROYECTO KOAJ ALEGRA | J12: JOMARK SEGURIDAD | K12: 2800000 | L12: 44568 | M12: X | N12: 3167344808 | O12: Daniel Echeverry Pérez | P12: proyectos3@jomarkseguridad.com
B13: 2 | C13: COTIZACION DE LOS DISEÑOS DE SEGURIDAD HUMANA Y PROTECCIÓN CONTRA INCENDIOS - PROYECTO 23 LIVING | J13: MENSULA | K13: 18550000 | L13: 44573 | N13: 300 864 37 10 | O13: Cristina Palacio Pérez | P13: cristinapalacio@mensulaingenieros.com
B14: 3 | C14: COTIZACION DEL DISEÑO DE EXTINCIÓN DE INCENDIOS - IBC CALDAS | J14: SPCI | K14: 9950000 | L14: 44573 | N14: 3104680508 | O14: Juan Pablo Grajales | P14: juan.grajales@spci.com.co
B15: 4 | C15: COTIZACION DEL DISEÑO DE DETECCIÓN DE INCENDIOS - ATENEA FAMLIA SANCELA | J15: SERIINCO | K15: 4500000 | L15: 44573 | M15: X | N15: 4442074 | O15: Francisco Unda | P15: francisco.unda@seriinco.com
B16: 5 | C16: COTIZACION DEL DISEÑO DE DETECCIÓN DE INCENDIOS PARA EL PROYECTO LOCAL FRISBY VIVA PALMA | J16: SPCI | K16: 950000 | L16: 44574 | N16: 3137546144 | O16: Juan Camilo Quintero Bedoya | P16: camilo.quintero@spci.com.co
B17: 6 | C17: COTIZACION DE LOS DISEÑOS DE PROTECCIÓN CONTRA INCENDIOS Y SEGURIDAD HUMANA PARA EL PROYECTO PLANTA Mr BONO | J17: SERVICIO IPM | K17: 22750000 | L17: 44574 | N17: 301 542 1412 | O17: Juan Santiago Londoño Quiceno | P17: juan.londono@serviciosipm.com
B18: 7 | C18: COTIZACION DE LOS DISEÑOS DE PROTECCIÓN CONTRA INCENDIOS PARA EL PROYECTO CAMINO DEL VIENTO TORRE 4 | J18: BIENES Y BIENES | K18: 11800000 | L18: 44575 | M18: X | N18: 311 - 8500 Ext.187 | O18: Jazzmín Restrepo Ortiz | P18: jrestrepo@bienesybienes.com.co
B19: 8 | C19: COTIZACION DEL DISEÑO SOPORTES SISMORRESISTENTE ZENÚ SPCI | J19: SPCI | K19: 690000 | L19: 44578 | M19: X | N19: 3104278593 | O19: Daniel Uribe | P19: dir.tecnico@spcisas.com.co
B20: 9 | C20: COTIZACION DE LOS DISEÑOS DE PROTECCIÓN CONTRA INCENDIOS Y SEGURIDAD HUMANA PARA EL PROYECTO HOTEL LA CASTELLANA | J20: RRP ARQUITECTOS | K20: 9400000 | L20: 44579 | O20: Gustavo Canchila | P20: gustavo.canchila@udea.edu.co
B21: 10 | C21: COTIZACION DEL DISEÑO DE EXTINCIÓN DE INCENDIOS PARA EL PROYECTO LOCAL VIVA ENVIGADO- QBANO | J21: SPCI | K21: 1000000 | L21: 44579 | M21: X | O21: Ana Maria Restrepo Mayo | P21: ana.restrepo@spci.com.co
B22: 11 | C22: COTIZACION DE LOS DISEÑOS DE PROTECCIÓN CONTRA INCENDIOS PARA EL PROYECTO PLANTA COOLFOOD | J22: INGENIO BIM | K22: 7450000 | L22: 44581 | N22: 3012311524 | O22: Luisa Fernanda Londoño Ciro | P22: luisa.londono@ingeniobim.co
B23: 12 | C23: COTIZACION DE REVISIÓN Y PRUEBAS DE LOS SISTEMAS DE PROTECCIÓN CONTRA INCENDIOS INSTALADOS Y LA SEGURIDAD HUMANA PARA EL PROYECTO BIO26 | J23: GERENCIA INTEGRAL | K23: 11750000 | L23: 44580 | N23: 57 312 2967935 | O23: Maria Teresa | P23: mlopez@hdgerenciaintegral.com
B24: 13 | C24: COTIZACION DE LOS DISEÑOS DE EXTINCIÓN DE INCENDIOS Y SEGURIDAD HUMANA PARA EL PROYECTO LOCAL COMFAMA CIS PLAZA FABRICATO | J24: INTERVE | K24: 5850000 | L24: 44580 | M24: X | N24: 310 386 17 63 | O24: Dario Antonio Saldarriaga Ramirez | P24: dsaldarriaga@interve.co
B25: 14 | C25: COTIZACION DEL DISEÑO DE EXTINCIÓN DE INCENDIOS - VORTEX AEROCAFE | J25: SFIRE | K25: 3150000 | L25: 44581 | N25: (57) 3108227462 | O25: Alvaro Manosalva | P25: alvaromanosalva@sfiregroup.com
B26: 15 | C26: COTIZACION DE LOS DISEÑOS DE PROTECCIÓN CONTRA INCENDIOS PARA EL PROYECTO FELICITY TORRE 3 Y 4 | J26: GINO | K26: No se cotizó | L26: 44581 | O26: Gino Montoya | P26: gino1037@hotmail.com
B27: 16 | C27: COTIZACION DE LOS DISEÑOS DE PROTECCIÓN CONTRA INCENDIOS PARA EL PROYECTO URBANIZACION SAN MIGUEL | J27: GINO | K27: 25930000 | L27: 44582 | O27: Gino Montoya | P27: gino1037@hotmail.com
B28: 17 | C28: COTIZACION DEL DISEÑO DE EXTINCIÓN DE INCENDIOS PARA EL PROYECTO OFICINA JOMARK | J28: JOMARK SEGURIDAD | K28: 1350000 | L28: 44582 | N28: 3147943785 | O28: Laura Duque Betancur | P28: proyectos2@jomarkseguridad.com
B29: 18 | C29: COTIZACION DEL DISEÑO DE EXTINCIÓN DE INCENDIOS PARA EL PROYECTO TANQUES SUR Y NORTE | J29: SERIINCO | K29: 11290000 | L29: 44586 | N29: 3113391008 | O29: Carlos Enrique Henao | P29: carlos.henao@seriinco.com
B30: 19 | C30: COTIZACION DE LOS DISEÑOS DE PROTECCIÓN CONTRA INCENDIOS PARA EL PROYECTO NOMBRE PROYECTO OFICINA JOMARK | J30: JOMARK SEGURIDAD | K30: 2025000 | L30: 44582 | N30: 3147943785 | O30: Laura Duque Betancur | P30: proyectos2@jomarkseguridad.com
B31: 20 | C31: COTIZACION DEL DISEÑO DE EXTINCIÓN DE INCENDIOS PARA EL PROYECTO VIVACE TORRE 3 | J31: SPCI | K31: 3135000 | L31: 44586 | M31: X | N31: 310 420 3649 | O31: Mauricio Guzmán Urrea | P31: mauricio.guzman@spci.com.co
B32: 21 | C32: COTIZACION DEL DISEÑO DE EXTINCIÓN DE INCENDIOS PARA EL PROYECTO LOCAL GLOW PARTY 11 | J32: SPCI | K32: 1000000 | L32: 44586 | N32: 3104680508 | O32: Juan Pablo Grajales | P32: juan.grajales@spci.com.co
B33: 22 | C33: COTIZACION DEL DISEÑO DE EXTINCIÓN DE INCENDIOS PARA EL PROYECTO LOCAL KUBIKA 7 | J33: SPCI | K33: 1000000 | L33: 44586 | N33: 3104680508 | O33: Juan Pablo Grajales | P33: juan.grajales@spci.com.co
B34: 23 | C34: COTIZACION DE LOS DISEÑOS DE PROTECCIÓN CONTRA INCENDIOS PARA EL PROYECTO MALL ZONA SUR | J34: PROJECT&SOLUCTION | K34: 9970000 | L34: 44586 | O34: Sebastián López Duque | P34: gerencia@projectsolutions.com.co
B35: 24 | C35: COTIZACION DE LOS DISEÑOS DE PROTECCIÓN CONTRA INCENDIOS PARA EL PROYECTO CES CENTRO AMBULATORIO CONSULTA EXTERNA CLINICA | J35: JOMARK SEGURIDAD | K35: 8150000 | L35: 44586 | M35: X | N35: 3147943785 | O35: Laura Duque Betancur | P35: proyectos2@jomarkseguridad.com
B36: 25 | C36: COTIZACION DEL ANÁLISIS DE SEGURIDAD HUMANA PARA EL PROYECTO COLSANITAS CARTAGENA DEL MAR | J36: CONDISEÑO | K36: 5500000 | L36: 44586 | N36: 3175594091 | O36: Nakary García Romero | P36: n.garcia@condiseno.co
B37: 26 | C37: COTIZACION DE LOS RE-DISEÑOS DE PROTECCIÓN CONTRA INCENDIOS Y SEGURIDAD HUMANA PARA EL PROYECTO MAZANTI ETAPA 1 Y 2 | J37: CONSTRUIR OBRAS CIVILES | K37: 6590000 | L37: 44593 | M37: X | N37: 3206284446 | O37: Diana Marcela Cardona Lopez | P37: direccionmazanti@gmail.com
B38: 27 | C38: COTIZACION DE LOS DISEÑOS DE SEGURIDAD HUMANA Y PROTECCIÓN CONTRA INCENDIOS - BANREP BOGOTA | J38: CONVEL | K38: 6590000 | L38: 44587 | N38: 300 258 90 33 | O38: Diana Perez | P38: dianaperez@convel.co
B39: 28 | C39: COTIZACION DE REVISIÓN DE LOS DISEÑOS DE PROTECCIÓN CONTRA INCENDIO - PROYECTO DV | J39: MENSULA | K39: 5400000 | L39: 44465 | M39: X | N39: 57 314 619 81 44 | O39: Angela Bravo | P39: angelabravo@mensulaingenieros.com
B40: 29 | C40: COTIZACION DEL ANÁLISIS DE SEGURIDAD HUMANA PARA EL PROYECTO PISCINAS DEL COMPLEJO ACUATICO | J40: DESUR | K40: 2500000 | L40: 44588 | M40: X | N40: 4801300 Ext. 137 | O40: Olmes Fernando Rodríguez Álzate | P40: olmes.rodriguez@desur.gov.co
B41: 30 | C41: COTIZACION DEL ANÁLISIS DE SEGURIDAD HUMANA - CEDI MARINILLA | J41: CONCONCRETO | K41: 7950000 | L41: 44588 | N41: 314 8646158 | O41: Francisco Restrepo | P41: fjrestrepo@conconcreto.com
B42: 31 | C42: COTIZACION DEL ANÁLISIS DE SEGURIDAD HUMANA - AMPLIACIÓN SEDE PALMIRA | J42: CONCONCRETO | K42: 4750000 | L42: 44588 | N42: 314 8646158 | O42: Francisco Restrepo | P42: fjrestrepo@conconcreto.com
B43: 32 | C43: COTIZACION DE LOS DISEÑOS DE PROTECCIÓN CONTRA INCENDIOS Y SEGURIDAD HUMANA PARA EL PROYECTO LEGADO ETAPA 1 | J43: FCR SAS | K43: 8470000 | L43: 44589 | M43: X | O43: LUZ STELLA IBARRA ARCILA | P43: stellaibarra@gmail.com
B44: 33 | C44: COTIZACION DE LOS DISEÑOS DE PROTECCIÓN CONTRA INCENDIOS Y SEGURIDAD HUMANA PARA EL PROYECTO RUTA 39 | J44: FCR SAS | K44: 17890000 | L44: 44589 | O44: LUZ STELLA IBARRA ARCILA | P44: stellaibarra@gmail.com
B45: 34 | C45: COTIZACION DEL DISEÑO DE EXTINCIÓN DE INCENDIOS PARA EL PROYECTO COMPLEX | J45: GINO | K45: 15000000 | L45: 44593 | O45: Gino Montoya | P45: gino1037@hotmail.com
B46: 35 | C46: COTIZACION DE LOS DISEÑOS DE PROTECCIÓN CONTRA INCENDIOS PARA EL PROYECTO SAJONIA | J46: CONTEX | K46: 5950000 | L46: 44592 | M46: X | O46: Astrid Jhoana Montoya Arias | P46: amontoya@contex.com.co
B47: 36 | C47: COTIZACION DE LOS DISEÑOS DE PROTECCIÓN CONTRA INCENDIOS Y SEGURIDAD HUMANA PARA EL PROYECTO MOKARA | J47: FCR SAS | K47: 18990000 | L47: 44593 | M47: X | O47: Daniela Vélez Cortés | P47: danielavelez.fcr@gmail.com
B48: 37 | C48: COTIZACION DEL DISEÑO DE DETECCIÓN DE INCENDIOS PARA EL PROYECTO AGENCIA MEDELLIN | J48: SPCI | K48: 3950000 | L48: 44593 | O48: Daniel Uribe Sierra | P48: daniel.uribe@spci.com.co
B49: 38 | C49: COTIZACION DE LOS DISEÑOS DE PROTECCIÓN CONTRA INCENDIOS Y SEGURIDAD HUMANA PARA EL PROYECTO FRAGUA (BELVERDE 3) | J49: CONTEX | K49: 20500000 | L49: 44593 | M49: X | O49: Elisa Pantoja Bohorquez | P49: epantoja@contex.com.co
...

Sheet 2023
E3: SEGUIMIENTO A COTIZACIONES
B11: Número de cotización | C11: Descripción de la cotización | J11: Cliente | K11: Valor sin IVA | L11: Fecha de cotización | M11: Aprobado | N11: Telefono | O11: Persona Encargada | P11: Correo
B12: 1 | C12: COTIZACION DE LOS DISEÑOS DE PROTECCIÓN CONTRA INCENDIOS - PROYECTO SOLAR | J12: SFIRE | L12: 44929 | N12: 310 8227462 | O12: Alvaro Manosalva | P12: alvaromanosalva@sfiregroup.com
B13: 2 | C13: COTIZACION DEL DISEÑO DE DETECCIÓN DE INCENDIOS - LA ESTRELLA | J13: GINO MONTOYA | K13: 5500000 | L13: 44930 | N13: 3044003430 | O13: Gino Montoya | P13: gino1037@hotmail.com
B14: 3 | C14: COTIZACION DEL DISEÑO DE DETECCIÓN DE INCENDIOS - LA MAYORISTA | J14: GINO MONTOYA | K14: 2500000 | L14: 44930 | N14: 3044003430 | O14: Gino Montoya | P14: gino1037@hotmail.com
B15: 4 | C15: COTIZACION DEL DISEÑO DE EXTINCIÓN DE INCENDIOS - MODELACIÓN Y CÁLCULOS LA CAUSA PF | J15: MAURICIO SEPULVEDA | K15: 500000 | L15: 44930 | N15: 301 2547727 | O15: Mauricio Sepulveda | P15: obrasms84@gmail.com
B16: 5 | C16: COTIZACION DE LOS DISEÑOS DE PROTECCIÓN CONTRA INCENDIOS Y SEGURIDAD HUMANA PARA EL PROYECTO LIBERTAD DE LA FORTUNA | J16: CONSTRUGEN | K16: 9910000 | L16: 44938 | N16: 3044830834 | O16: Jhonatan Aguirre Pulgarin | P16: jhonatan.aguirre@construgen.com
B17: 6 | C17: COTIZACION DE LOS DISEÑOS DE PROTECCIÓN CONTRA INCENDIOS - HOSPITAL REGIONAL DE DUITAMA | J17: HOSPITAL REGIONAL DE DUITAMA | K17: 29970000 | L17: 44942 | N17: 3133195098 | O17: Luis Orlando Cepeda Zarate | P17: mantenimiento@hrd.gov.co
B18: 7 | C18: COTIZACION DEL DISEÑO DE DETECCIÓN DE INCENDIOS - BODEGA LEBRIJA | J18: SPCI | K18: 6270000 | L18: 44942 | M18: X | N18: 310 3939739 | O18: Victor Saldarriaga | P18: victor.saldarriaga@spci.com.co
B19: 8 | C19: COTIZACION DEL DISEÑO DE EXTINCIÓN DE INCENDIOS - ÁREAS SIN PROTECCIÓN BODEGA LEBRIJA | J19: SPCI | K19: 5890000 | L19: 44942 | M19: X | N19: 310 3939739 | O19: Victor Saldarriaga | P19: victor.saldarriaga@spci.com.co
B20: 9 | C20: COTIZACION DE LOS DISEÑOS DE SEGURIDAD HUMANA Y PROTECCIÓN CONTRA INCENDIOS - OFICINAS ANDERCOL | J20: INGENIO BIM | K20: 5070000 | L20: 44942 | M20: X | N20: 301 2311524 | O20: Luisa Londoño | P20: luisa.londono@ingeniobim.co
B21: 10 | C21: COTIZACION DE LOS DISEÑOS DE PROTECCIÓN CONTRA INCENDIOS PARA EL PROYECTO JUAN VALDÉZ C.C VIVA BARRANQUILLA | J21: SPCI | K21: 2250000 | L21: 44945 | N21: 3214826168 | O21: Ana Maria Restrepo Mayo | P21: ana.restrepo@spci.com.co
B22: 11 | C22: COTIZACION DEL DISEÑO DE DETECCIÓN DE INCENDIOS PARA EL PROYECTO HOTEL AYACUCHO | J22: SOCOMES | K22: 2990000 | L22: 44945 | N22: 3137851941 | O22: David Lopera Medina | P22: david.lopera@socomes.com
B23: 12 | C23: COTIZACION DEL DISEÑO DE EXTINCIÓN DE INCENDIOS PARA EL PROYECTO HOTEL AYACUCHO | J23: SOCOMES | K23: 6270000 | L23: 44945 | N23: 3137851941 | O23: David Lopera Medina | P23: david.lopera@socomes.com
B24: 13 | C24: COTIZACION DE LOS DISEÑOS DE SEGURIDAD HUMANA Y PROTECCIÓN CONTRA INCENDIOS - PROYECTO ALLEGRO | J24: CENTRO SUR | K24: 7470000 | L24: 44944 | M24: X | N24: 4480648 | O24: Daniel Pernett Patiño | P24: danielpernett@centrosur.co
B25: 14 | C25: COTIZACION DE LOS DISEÑOS DE PROTECCIÓN CONTRA INCENDIOS PARA EL PROYECTO EDIFICIO LA 33 | J25: CONSTRUCTORA MANZANARES | K25: 7900000 | L25: 44946 | N25: 312 8667618 | O25: Álvaro Pérez | P25: apb2573@yahoo.es
B26: 15 | C26: COTIZACION DEL ANÁLISIS DE SEGURIDAD HUMANA PARA EL PROYECTO JAC DEL OASIS | J26: DESUR | K26: 2500000 | L26: 44946 | N26: 4801300 Ext. 130 | O26: Valentina Chacon | P26: valentina.chacon@desur.gov.co
B27: 16 | C27: COTIZACION DE LOS DISEÑOS DE PROTECCIÓN CONTRA INCENDIOS Y SEGURIDAD HUMANA PARA EL PROYECTO CIUDAD DEL RIO | J27: 4RQ STUDIO | K27: 31520000 | L27: 44953 | N27: 3128882282 | O27: Katherine Lopez Ramirez | P27: equipo@4rqstudio.com
B28: 17 | C28: COTIZACION DEL DISEÑO DE EXTINCIÓN DE INCENDIOS - PROYECTO VIVACE TORRE 2 | J28: SPCI | K28: 3600000 | L28: 44949 | M28: X | N28: 310 420 3649 | O28: Mauricio Guzmán Urrea | P28: mauricio.guzman@spci.com.co
B29: 17 | C29: COTIZACION DE LOS DISEÑOS DE PROTECCIÓN CONTRA INCENDIOS Y SEGURIDAD HUMANA PARA EL PROYECTO EDIFICIO NUEVO COLEGIO THE COLUMBUS SCHOOL | J29: Colegio The Columbus School | K29: 3450000 | L29: 44950 | M29: X | N29: 312 2886611 | O29: Paula Andrea Duque | P29: pduque@columbus.edu.co
B30: 18 | C30: COTIZACION DE LOS DISEÑOS DE PROTECCIÓN CONTRA INCENDIOS PARA EL PROYECTO HOSPITALIZACION TPH SEDE 80 | J30: AUNA | K30: 1950000 | L30: 44951 | M30: X | N30: 57 60 4 342 10 10 | O30: Cristian David Cano | P30: cristian.cano@lasamericas.com.co
B31: 19 | C31: COTIZACION DE LOS DISEÑOS DE PROTECCIÓN CONTRA INCENDIOS PARA EL PROYECTO LOCAL CONSULTORIO ODONTOLOGICO C.C VIVA SINCELEJO | J31: SPCI | K31: 2510000 | L31: 44952 | N31: 3214826168 | O31: Ana Maria Restrepo Mayo | P31: licitaciones@spci.com.co
B32: 20 | C32: COTIZACION DE LOS DISEÑOS DE PROTECCIÓN CONTRA INCENDIOS PARA EL PROYECTO CALLE 7 A | J32: PARADIGMA ARQUITECTURA | K32: 23650000 | L32: 44952 | O32: Juliana Cardona | P32: paradigmaarquitecturasas@gmail.com
B33: 21 | C33: COTIZACION DE LOS DISEÑOS DE PROTECCIÓN CONTRA INCENDIOS Y SEGURIDAD HUMANA PARA EL PROYECTO CALLE 7A | J33: SECURETEC | K33: 23650000 | L33: 44952 | O33: Harold Camacho | P33: gerencia@securetec.com.co
B34: 22 | C34: COTIZACION PLANOS DE SEGURIDAD HUMANA - PROYECTO FRAGUA | J34: CONTEX | K34: 2350000 | L34: 44952 | M34: X | N34: 317 3789177 | O34: Elisa Pantoja | P34: epantoja@contex.com.co
B35: 23 | C35: COTIZACION DEL DISEÑO DE EXTINCIÓN DE INCENDIOS PARA EL PROYECTO GENERSOL | J35: SFIRE | K35: 12550000 | L35: 44953 | N35: 3108227462 | O35: ALVARO MANOSALVA | P35: alvaromanosalva@sfiregroup.com
B36: 24 | C36: COTIZACION DE LOS DISEÑOS DE PROTECCIÓN CONTRA INCENDIOS PARA EL PROYECTO BANCOLOMBIA UNICENTRO | J36: CONDISEÑO | L36: 44953 | N36: 3175594091 | O36: Nakary García Romero | P36: n.garcia@condiseno.co
B37: 25 | C37: COTIZACION DEL ANÁLISIS DE SEGURIDAD HUMANA PARA EL PROYECTO OFICINAS | J37: STUDIO SUR | K37: 3550000 | L37: 44953 | M37: X | P37: liliana.gutierrez@studiosur.net -laura.arias@studiosur.net
B38: 26 | C38: COTIZACION DEL DIAGNÓSTICO DE LOS SISTEMAS DE PROTECCIÓN CONTRA INCENDIOS - CLÍNICA IMBANACO CALI | J38: IMBANACO | K38: 14300000 | L38: 44957 | N38: 3205535416 | O38: Camilo Andrés Chávez Sandoval | P38: Camilo.Chavez@quironsalud.com
B39: 27 | C39: COTIZACION DE LOS DISEÑOS DE PROTECCIÓN CONTRA INCENDIOS PARA EL PROYECTO PORCI CARNES | J39: SPCI | K39: 6900000 | L39: 44957 | N39: 310 4165783 | O39: Cristiam Gustavo Mondragon Cortes | P39: cristiam.mondragon@spci.com.co
B40: 28 | C40: COTIZACION DE LOS DISEÑOS DE PROTECCIÓN CONTRA INCENDIOS PARA EL PROYECTO BODEGA 23 REPOTENCIACION SCI | J40: SPCI | K40: 39950000 | L40: 44957 | N40: 310 4165783 | O40: Cristiam Gustavo Mondragon Cortes | P40: cristiam.mondragon@spci.com.co
B41: 29 | C41: COTIZACION DEL ANÁLISIS DE SEGURIDAD HUMANA PARA EL PROYECTO REASENTAMIENTO GRAMALOTE FASE 1 EN COLOMBIA | J41: CONCONCRETO | K41: 3950000 | L41: 44957 | M41: X | O41: Sara Restrepo
B42: 30 | C42: COTIZACION DEL ANÁLISIS DE SEGURIDAD HUMANA PARA EL PROYECTO TULIO OSPINA | J42: Kevin Batista | K42: 13540000 | L42: 44957 | N42: 3023105548 | O42: Kevin Batista | P42: kevin15batista@gmail.com
B43: 31 | C43: COTIZACION DEL DISEÑO SOPORTES SISMORRESISTENTE RESERVA DEL PARQUE | J43: SPCI | K43: 690000 | L43: 44958 | N43: 3146920966 | O43: Daniel Uribe | P43: daniel.uribe@spci.com.co
B44: 32 | C44: COTIZACION DE LOS DISEÑOS DE PROTECCIÓN CONTRA INCENDIOS Y SEGURIDAD HUMANA PARA EL PROYECTO COLEGIO JOSE MARIA MANYANET | J44: Aguas Ingeniería Medellín | K44: 11790000 | L44: 44959 | N44: 3015743970-3192090844-3226861576 | O44: Andrés Ardila Duque | P44: aguasingenieriamed@gmail.com
B45: 33 | C45: COTIZACION DE LOS DISEÑOS DE PROTECCIÓN CONTRA INCENDIOS Y SEGURIDAD HUMANA PARA EL PROYECTO CLINICA KRA 49B | J45: VIVA 1A IPS | K45: 10970000 | L45: 44959 | N45: 3156648484 | O45: Juan Alberto Fontalvo Polo | P45: jfontalvo@viva1a.com.co
B46: 34
B47: 35 | C47: COTIZACION DE LOS DISEÑOS DE PROTECCIÓN CONTRA INCENDIOS Y SEGURIDAD HUMANA PARA EL PROYECTO CAFETERIA ELEMENTAL | J47: Colegio The Columbus School | K47: 7450000 | L47: 44959 | M47: X | N47: 312 2886611 | O47: Paula Andrea Duque | P47: pduque@columbus.edu.co
B48: 36 | C48: COTIZACION DE LOS DISEÑOS DE PROTECCIÓN CONTRA INCENDIOS Y SEGURIDAD HUMANA PARA EL PROYECTO VERMONTE MODIFICACION PISO 1 | J48: Con-axion S.A.S. | K48: 7450000 | L48: 44959 | M48: X | N48: (4) 440 9310 | O48: JORGE O. TORO MONTES | P48: jtoro@con-axion.com
B49: 37 | C49: COTIZACION DEL ANÁLISIS DE SEGURIDAD HUMANA PARA EL PROYECTO LOS CAMBULOS | J49: Constructora Guasandi s.a.s | K49: 4500000 | L49: 44960 | N49: 323 5893023 y/o (604)5609600 ext.104. | O49: Angélica Patiño | P49: diseno@constructoradeobras.com
...

Sheet 2024
E3: SEGUIMIENTO A COTIZACIONES
B11: Número de cotización | C11: Descripción de la cotización | J11: Cliente | K11: Valor sin IVA | L11: Fecha de cotización | M11: Aprobado | N11: Telefono | O11: Persona Encargada | P11: Correo
B12: 1
B13: 2 | C13: COTIZACION DE LOS DISEÑOS DE PROTECCIÓN CONTRA INCENDIOS Y SEGURIDAD HUMANA PARA EL PROYECTO ENTRE AIRES | J13: INSERCO | K13: 34950000 | L13: 45303 | N13: 3104131109 | O13: Leandro Herrera Gutierrez | P13: directorlean@inserco.com.co
B14: 3 | C14: COTIZACION DEL DISEÑO DE EXTINCIÓN DE INCENDIOS - SERVICENTRO EL CAMPESTRE | J14: K&J INGENIEROS S.A.S | K14: 6950000 | L14: 45303 | O14: Karla Rendón | P14: krendon@kyjingenieros.co
B15: 4 | C15: COTIZACION DE LOS DISEÑOS DE SEGURIDAD HUMANA Y PROTECCIÓN CONTRA INCENDIOS - LICEO FRANCES EXISTENTE | J15: LICEO FRANCES | K15: 11950000 | L15: 45303 | O15: Andrés Ramírez | P15: administrativo2@lf.edu.co
B16: 5 | C16: COTIZACION DEL ANÁLISIS DE SEGURIDAD HUMANA PARA EL PROYECTO NUEVA SEDE DE LA TORRE ESE HOSPITAL SAN VICENTE | J16: Consorcio HSVA | K16: 4250000 | L16: 45303 | N16: 3164313039 | O16: CARLOS ORJUELA | P16: caleorca26@gmail.com
B17: 6 | C17: COTIZACION DE LOS DISEÑOS DE PROTECCIÓN CONTRA INCENDIOS PARA EL PROYECTO OFICINA 11-01 DEL CCI | J17: SPCI | K17: 2830000 | L17: 45308 | N17: 3104165783 | O17: Cristiam Gustavo Mondragon | P17: dir.tecnico@spci.com.co
B18: 7 | C18: COTIZACION DEL REDISEÑO DE EXTINCIÓN DE INCENDIOS PARA EL PROYECTO ARAGUA | J18: SPCI | K18: 1000000 | L18: 45308 | N18: 3104165783 | O18: Cristiam Gustavo Mondragon | P18: dir.tecnico@spci.com.co
B19: 8 | C19: COTIZACION DEL DISEÑO DE DETECCIÓN DE INCENDIOS PARA EL PROYECTO PLANTA ZEUUS GIRARDOTA | J19: SERIINCO | K19: 7950000 | L19: 45306 | N19: 3113391008 | O19: Carlos Henao | P19: carlos.henao@seriinco.com
B20: 9 | C20: COTIZACION DE LOS DISEÑOS DE PROTECCIÓN CONTRA INCENDIOS Y SEGURIDAD HUMANA PARA EL PROYECTO HOTEL HAVEN | J20: Mensula | K20: 11950000 | L20: 45306 | N20: 311 6751810 | O20: Valentina Ortega Morales | P20: valentinaortega@mensulaingenieros.com
B21: 10 | C21: COTIZACION DE LOS DISEÑOS DE PROTECCIÓN CONTRA INCENDIOS PARA EL PROYECTO BELIVE | J21: COMEX INTERNACIONAL SAS | K21: 14950000 | L21: 45307 | N21: 316 496 20 26 | O21: Juan David Ossa Salazar | P21: comercial@comexinternacional.com.co
B22: 11 | C22: COTIZACION DEL ANÁLISIS DE SEGURIDAD HUMANA PARA EL PROYECTO PLANTA SIKA RIONEGRO | J22: JOMARK | K22: 7950000 | L22: 45308 | N22: 3194913179 | O22: Carlos Almanya Patiño | P22: calmanya@jomarkseguridad.com
B23: 12 | C23: COTIZACIÓN REDISEÑO DE EXTINCIÓN DE INCENDIOS PARA EL PROYECTO OFICINAS LEBRIJA PISO 2 MEZANINE | J23: SPCI | K23: 2950000 | L23: 45308 | N23: 3229057647 | O23: José Luis Ojeda Caarvajal | P23: jose.ojeda@spci.com.co
B24: 13 | C24: COTIZACION DE LA INGENIERÍA CONCEPTUAL DE PROTECCIÓN CONTRA INCENDIOS PARA EL PROYECTO - PLANTA DE ACEITE | J24: INGESED | K24: 9950000 | L24: 45310 | N24: 313 540 17 14 | O24: Eliana Isabel Cardona Ríos | P24: comercial@ingesed.com
B25: 14 | C25: COTIZACION DE LOS DISEÑOS DE SEGURIDAD HUMANA Y PROTECCIÓN CONTRA INCENDIOS - RESERVA CENTRAL | J25: GO INGENIERÍA Y SOLUCIONES | K25: 19940000 | L25: 45309 | N25: 310 5104288 | O25: Cristian Gañan
B26: 15 | C26: COTIZACION DE LOS DISEÑOS DE SEGURIDAD HUMANA Y PROTECCIÓN CONTRA INCENDIOS - 380 M2 CLÍNICA NOEL | J26: GO INGENIERÍA Y SOLUCIONES | K26: 4760000 | L26: 45309 | N26: 310 5104288 | O26: Cristian Gañan
B27: 16 | C27: COTIZACIÓN DE LA MODELACIÓN DE LA RED GENERAL DE EXTINCIÓN DE INCENDIOS PARA EL PROYECTO | J27: SOCOMES | K27: 2500000 | L27: 45309 | N27: 3137851941 | O27: David Lopera medina | P27: david.lopera@socomes.com
B28: 17 | C28: COTIZACION DE LOS DISEÑOS DE PROTECCIÓN CONTRA INCENDIOS Y SEGURIDAD HUMANA PARA EL PROYECTO ARMENIA | J28: CONTEX | K28: 19950000 | L28: 45313 | N28: 3104145629 | O28: Maria Camila Velásquez | P28: mcvelasquez@contex.com.co
B29: 18 | C29: COTIZACIÓN DE LA ASESORIA EN SALIDA DE EMERGENCIA PARA PRIMER PISO DE EDUARDO BOTERO SOTO S.A. | J29: EDUARDO BOTERO SOTO S.A. | K29: 1880000 | L29: 45313 | N29: 3113507944 | O29: Milena Echeverri
B30: 19 | C30: COTIZACION DE LOS DISEÑOS DE PROTECCIÓN CONTRA INCENDIOS Y SEGURIDAD HUMANA PARA EL PROYECTO INCODOL MEDICAL TOWER | J30: SOLUCIONES INMOBILIARIAS | K30: 7530000 | L30: 45314 | N30: 3182079204 | O30: Deyner Jimenez | P30: residente3@solucionesinmobiliariassas.com
B31: 20 | C31: COTIZACION DE LOS DISEÑOS DE PROTECCIÓN CONTRA INCENDIOS Y SEGURIDAD HUMANA PARA EL PROYECTO NEUROMEDICA MEDICAL TOWER | J31: SOLUCIONES INMOBILIARIAS | K31: 14430000 | L31: 45314 | N31: 3182079204 | O31: Deyner Jimenez | P31: residente3@solucionesinmobiliariassas.com
B32: 21 | C32: COTIZACION DE LOS DISEÑOS DE PROTECCIÓN CONTRA INCENDIOS PARA EL PROYECTO ARL SURA VIVA ENVIGADO | J32: Ingenieria y Montajes | K32: 6250000 | L32: 45314 | N32: 3175179593 | O32: Diego Alejandro Correa Bedoya | P32: dacorrea@rcimontajes.co
B33: 22 | C33: COTIZACION DE REVISIÓN DE LOS DISEÑOS DE PROTECCIÓN CONTRA INCENDIO Y SEGURIDAD HUMANA - PTAR ESCOBERO | J33: SPCI | K33: 3150000 | L33: 45315 | N33: 310 468 0508 | O33: Juan Pablo Grajales Gómez | P33: juan.grajales@spci.com.co
B34: 23 | C34: COTIZACION DEL ANÁLISIS DE SEGURIDAD HUMANA PARA EL PROYECTO TORRE DE LA ALIANZA | J34: SOLUCIONES INMOBILIARIAS | K34: 2750000 | L34: 45315 | N34: 3006731128 | O34: Laura Olano | P34: gcia.torresalianza@solucionesinmobiliariassas.com
B35: 24 | C35: COTIZACION DE LA REVISIÓN DE SEGURIDAD HUMANA Y LOS SISTEMAS DE PROTECCIÓN CONTRA INCENDIOS PARA CLÍNICA EN SINCELEJO | J35: CONDISEÑO | K35: 6500000 | L35: 45316 | N35: 3175594091 | O35: Nakary Garcia Romero | P35: n.garcia@condiseno.co
B36: 25 | C36: COTIZACION DE LOS DISEÑOS DE PROTECCIÓN CONTRA INCENDIOS Y SEGURIDAD HUMANA PARA EL PROYECTO USHUAYA | J36: EDYFYCA | K36: 26350000 | L36: 45317 | N36: 3104057513 | O36: Claudia Ramirez | P36: claudia.ramirez@edyfica.co
B37: 26 | C37: COTIZACION DE LOS DISEÑOS DE EXTINCIÓN DE INCENDIOS Y SEGURIDAD HUMANA PARA EL PROYECTO IE RIO GRANDE | J37: Londoño Gomez | K37: 5650000 | L37: 45317 | N37: 3111770 ext 177 | O37: Juan Diego Echeverri | P37: jecheverri@londonogomez.com
B38: 27 | C38: COTIZACION DEL DISEÑO DE EXTINCIÓN DE INCENDIOS PARA EL PROYECTO CLINICA LLANO GRANDE | J38: ML ARQUITECTURA | K38: 1450000 | L38: 45317 | O38: Melissa Lopez Torres | P38: melissalopez@mltarq.com
B39: 28 | C39: COTIZACION DEL DISEÑO DE DETECCIÓN DE INCENDIOS PARA EL PROYECTO PARQUE EMPRESARIAL ELITE II | J39: RCI Ingenieria y Montajes | K39: 4950000 | L39: 45317 | N39: 3175179593 | O39: Diego Alejandro Correa Bedoya | P39: dacorrea@rcimontajes.co
B40: 29 | C40: COTIZACION DE LOS DISEÑOS DE PROTECCIÓN CONTRA INCENDIOS Y SEGURIDAD HUMANA PARA EL PROYECTO CENTRO COMERCIAL X ORIENTE | J40: Arquitectura y Concreto | K40: 59950000 | L40: 45317 | N40: 3127218621 | O40: ROBINSON MARULANDA GUARIN | P40: robinsonmarulanda@arquitecturayconcreto.com
B41: 30 | C41: COTIZACION DEL DISEÑO DE EXTINCIÓN DE INCENDIOS PARA EL PROYECTO LOCALES MEDIPIEL DMODA | J41: SPCI | K41: 7170000 | L41: 45318 | N41: 3137546144 | O41: Juan Camilo Quintero Bedoya | P41: camilo.quintero@spci.com.co
B42: 31 | C42: COTIZACION DEL ANÁLISIS DE SEGURIDAD HUMANA PARA EL PROYECTO PLANTA BIOCLORO | J42: CONCONCRETO | K42: 8500000 | L42: 45320 | N42: 3003404902 | O42: Pilar Arango Restrepo | P42: parangor@conconcreto.com
B43: 32 | C43: COTIZACION DE LOS DISEÑOS DE PROTECCIÓN CONTRA INCENDIOS Y SEGURIDAD HUMANA PARA EL PROYECTO OBRA PREESCOLAR COLEGIO BENEDICTINOS | J43: Tamayo Ingenieros | K43: 6250000 | L43: 45320 | N43: 3137687548 | O43: Herbin Cartagena Montoya
B44: 33 | C44: COTIZACION DEL DISEÑO DE EXTINCIÓN DE INCENDIOS PARA EL PROYECTO PISO 19 CENTRO COMERCIAL LOS MOLINOS | J44: I+ CONSTRUCTORA | K44: 4350000 | L44: 45321 | N44: (604) 4443091 | O44: Lina Maria Montoya Gonzalez | P44: lmontoya@iconstructora.com.co
B45: 34 | C45: COTIZACIÓN DE LA ELABORACIÓN DIGITAL DE LAS PLACAS HIDRÁULICAS PARA JARDINES DE LLANOGRANDE | J45: SPCI | K45: 750000 | L45: 45321 | N45: 3137546144 | O45: Juan Camilo Quintero Bedoya | P45: camilo.quintero@spci.com.co
B46: 35 | C46: COTIZACION DEL DISEÑO DE DETECCIÓN DE INCENDIOS PARA EL PROYECTO PLANTA ZEUUS GIRARDOTA | J46: SERIINCO | K46: 6950000 | L46: 45323 | N46: 3113391008 | O46: Carlos Henao | P46: carlos.henao@seriinco.com
B47: 36 | C47: COTIZACION DE LOS DISEÑOS DE PROTECCIÓN CONTRA INCENDIOS PARA EL PROYECTO SUBESTACIONES EPM | J47: COINSI | K47: 214500000 | L47: 45324 | N47: 3117208541 | O47: Sergio Rodriguez | P47: diseno4@gyd.com.co
B48: 37 | C48: COTIZACION DE LOS DISEÑOS DE PROTECCIÓN CONTRA INCENDIOS Y SEGURIDAD HUMANA PARA EL PROYECTO CENTRO DE SALUD BARRIO GALÁN | J48: Pedro Quiros | K48: 7520000 | L48: 45324 | N48: 3123770102 | O48: Pedro Quiros | P48: pequibo1@gmail.com
B49: 38 | C49: COTIZACION DE LOS DISEÑOS DE PROTECCIÓN CONTRA INCENDIOS PARA EL PROYECTO BANDAS TRANSPORTADORAS | J49: JM Ingenieria | K49: 56500000 | L49: 45324 | O49: Joam Moreno | P49: gerencia@jmingenieriatotal.com.co
...

Sheet 2025
D2: SEGUIMIENTO A COTIZACIONES - 2025
B10: Número de cotización | C10: Descripción de la cotización | I10: Cliente | J10: Valor sin IVA | K10: Fecha de cotización | L10: Aprobado | M10: Telefono | N10: Persona Encargada | O10: Correo
B11: 1 | C11: COTIZACION DEL ANÁLISIS DE SEGURIDAD HUMANA - MALL LA KONDINA | I11: Raíz Constructora | J11: 4950000 | K11: 45666 | M11: 3113555383 | N11: Daniel Fernando Hernandez | O11: coordinadorobra@gruporaiz.com.co
B12: 2 | C12: COTIZACION DEL ANÁLISIS DE SEGURIDAD HUMANA - ALTA KONDINA | I12: Raíz Constructora | J12: 7550000 | K12: 45666 | M12: 3113555383 | N12: Daniel Fernando Hernandez | O12: coordinadorobra@gruporaiz.com.co
B13: 3 | C13: COTIZACION DE LOS DISEÑOS DE PROTECCIÓN CONTRA INCENDIOS - VILLA CAMPESTRE | I13: Fire y Equipos | J13: 15950000 | K13: 45670 | M13: 3134451063 | N13: Juan Jose Monsalve | O13: dir.proyectos@goodgroup.com.co
B14: 4 | C14: COTIZACION DE LOS DISEÑOS DE SEGURIDAD HUMANA Y PROTECCIÓN CONTRA INCENDIOS - OLMO | I14: Vértice | J14: 26590000 | K14: 45671 | M14: 3216438520 | N14: Luz Aleidy Cuartas Pérez | O14: dcv@altosdelaabadia.com
B15: 5 | C15: COTIZACION DE LOS DISEÑOS DE SEGURIDAD HUMANA Y DETECCIÓN DE INCENDIOS - VIEW POINT ETAPA 2 | I15: Coninsa | J15: 10960000 | K15: 45671 | M15: 3155264386 | N15: Yuliana Tamayo Zapata | O15: ytamayo@coninsa.co
B16: 6 | C16: COTIZACION DE LOS DISEÑOS DE SEGURIDAD HUMANA Y PROTECCIÓN CONTRA INCENDIOS - ACC Y ADS PAILITAS | I16: SRAIC | J16: Variable | K16: 45671 | M16: 3022295772 | N16: Aurora Rios | O16: proyectos@santiagorojas.com.co
B17: 7 | C17: CRISTIAM NO PASÓ A TIEMPO LA INFORMACIÓN Y NO SE PUDO COTIZAR EL PROYECTO | I17: SPCI | J17: NO SE COTIZÓ | K17: 45671 | M17: 3104165783 | N17: Cristiam Gustavo Mondragon | O17: dir.tecnico@spci.com.co
B18: 8 | C18: COTIZACION DEL DISEÑO DE DETECCIÓN DE INCENDIOS - DETECCIÓN ZONA GLP | I18: SPCI | J18: 2500000 | K18: 45671 | M18: 3104203649 | N18: Mauricio Guzman | O18: mauricio.guzman@spci.com.co
B19: 9 | C19: COTIZACION DE LOS DISEÑOS DE PROTECCIÓN CONTRA INCENDIOS - PLAZA DE MERCADO ANDES | I19: Socomes | J19: 13170000 | K19: 45671 | M19: 3137851941 | N19: David Lopera medina | O19: david.lopera@socomes.com
B20: 10 | C20: COTIZACION DE LOS DISEÑOS DE PROTECCIÓN CONTRA INCENDIOS - PLAZA DE MERCADO ANDES | I20: Ingesed | J20: 13170000 | K20: 45671 | M20: 3135401714 | N20: Eliana Isabel Cardona Ríos | O20: comercial@ingesed.com
B21: 11 | C21: COTIZACION DE LOS DISEÑOS DE SEGURIDAD HUMANA Y PROTECCIÓN CONTRA INCENDIOS - MIC GUARNE | I21: Jomark Seguridad SAS | J21: 19950000 | K21: 45671 | M21: 3194913179 | N21: Carlos Almanya Patiño | O21: calmanya@jomarkseguridad.com
B22: 12 | C22: COTIZACION DE LOS DISEÑOS DE SEGURIDAD HUMANA Y PROTECCIÓN CONTRA INCENDIOS - MAZDA VEGAS | I22: Jomark Seguridad SAS | J22: 19850000 | K22: 45671 | M22: 3194913179 | N22: Carlos Almanya Patiño | O22: calmanya@jomarkseguridad.com
B23: 13 | C23: COTIZACION DE LOS DISEÑOS DE SEGURIDAD HUMANA Y PROTECCIÓN CONTRA INCENDIOS - CANCHAS PADEL | I23: Coninsa | J23: 6950000 | K23: 45672 | M23: 3155264386 | N23: Yuliana Tamayo Zapata | O23: ytamayo@coninsa.co
B24: 14 | C24: COTIZACION DEL DISEÑO DE EXTINCIÓN DE INCENDIOS - BODEGA 4000 M2 LA ESTRELLA | I24: ITC Diseños | J24: 18000000 | K24: 45674 | M24: 3044003430 | N24: Gino Alejandro Montoya | O24: gino1037@hotmail.com
B25: 15 | C25: COTIZACION DE LOS DISEÑOS DE PROTECCIÓN CONTRA INCENDIOS - CREACIONES APICE | I25: SPCI | J25: 25810000 | K25: 45674 | M25: 3104165783 | N25: Cristiam Gustavo Mondragon | O25: dir.tecnico@spci.com.co
B26: 16 | C26: COTIZACION DEL ANÁLISIS DE SEGURIDAD HUMANA - EL PRADO | I26: OTACC | J26: 10670000 | K26: 45677 | M26: 3107195105 | N26: Alejandra Rodriguez Sandoval | O26: jrodriguez@otacc.com
B27: 17 | C27: COTIZACION DE LOS DISEÑOS DE SEGURIDAD HUMANA Y PROTECCIÓN CONTRA INCENDIOS - EL ESMERALDAL | I27: Ingesed | J27: 17950000 | K27: 45677 | M27: 3135401714 | N27: Eliana Isabel Cardona Ríos | O27: comercial@ingesed.com
B28: 18 | C28: COTIZACION DE LOS DISEÑOS DE SEGURIDAD HUMANA Y PROTECCIÓN CONTRA INCENDIOS - VERMONTE TORRE 3 | I28: Intervé | J28: 7650000 | K28: 45674 | M28: 3012409366 | N28: Humberto Acevedo | O28: hacevedo@interve.co
B29: 19 | C29: COTIZACION DE LOS DISEÑOS DE SEGURIDAD HUMANA Y PROTECCIÓN CONTRA INCENDIOS - PLAZA EL AGUA | I29: Condiseño | J29: 14850000 | K29: 45677 | M29: 3175594091 | N29: Nakary Garcia Romero | O29: n.garcia@condiseno.co
B30: 20 | C30: COTIZACION DE LOS DISEÑOS DE PROTECCIÓN CONTRA INCENDIOS Y SEGURIDAD HUMANA PARA EL PROYECTO MALL COMERCIAL NATAL | I30: RRP | J30: 11520000 | K30: 45677 | N30: Daniel Andrés Restrepo Ríos | O30: danielrestrepo0804@gmail.com
B31: 21 | C31: COTIZACION DE LOS DISEÑOS DE SEGURIDAD HUMANA Y PROTECCIÓN CONTRA INCENDIOS - PROYECTO GIN | I31: FCR | J31: 24840000 | K31: 45677 | M31: 310 5304562 | N31: Vanessa Zapata | O31: vanessazapata.fcr@gmail.com
B32: 22 | C32: COTIZACION DEL ANÁLISIS DE SEGURIDAD HUMANA - CLÍNICA PEDIÁTRICA COLSUBSIDIO | I32: Condiseño | J32: 14000000 | K32: 45678 | M32: 3175594091 | N32: Nakary Garcia Romero | O32: n.garcia@condiseno.co
B33: 23 | C33: COTIZACION DE LOS DISEÑOS DE PROTECCIÓN CONTRA INCENDIOS - PISOS 36 37 38 Y 40 TORRE COLPATRIA | I33: SPCI | J33: =7900000+4010000 -> 11910000 | K33: 45679 | M33: 3104165783 | N33: Cristiam Gustavo Mondragon | O33: dir.tecnico@spci.com.co
B34: 24 | C34: COTIZACION DE LOS PLANOS Y CANTIDADES DE SEÑALIZACIÓN DE EMERGENCIA - BODEGA CA-20 | I34: Fire Marshal | J34: 2500000 | K34: 45679 | M34: 3224188478 | N34: Andrea Núñez | O34: andreanunez@firemarshal.com.co
B35: 25 | C35: COTIZACION DEL ANÁLISIS DE SEGURIDAD HUMANA - SERENA | I35: Conconcreto | J35: 6270000 | K35: 45679 | M35: 3148721400 | N35: Adriana Agudelo López | O35: aagudelol@conconcreto.com
